<?xml version="1.0" ?>
<!-- =================================================================================== -->
<!-- |    This document was autogenerated by xacro from lunarbot.xacro                 | -->
<!-- |    EDITING THIS FILE BY HAND IS NOT RECOMMENDED                                 | -->
<!-- =================================================================================== -->
<!--Name of robot-->
<robot name="Roberto_MkI">
  <!--Naming Materials-->
  <material name="blue">
    <color rgba="0 0 0.8 1"/>
  </material>
  <material name="white">
    <color rgba="1 1 1 1"/>
  </material>
  <!--Add <gazebo> element to <robot>, <link>, and <joint> elements-->
  <gazebo>
	</gazebo>
  <!--Links-->
  <!--Body(base_link)-->
  <link name="base_link">
    <!--Visual-->
    <visual>
      <geometry>
        <box size="1.0 0.6 0.3"/>
      </geometry>
      <material name="white"/>
    </visual>
    <!--Collision-->
    <collision>
      <geometry>
        <box size="1.0 0.6 0.3"/>
      </geometry>
    </collision>
    <inertial>
      <mass value="108.09"/>
      <!--inertia: required by Gazebo-->
      <!--6 values: ixx ixy ixz iyy iyz izz-->
      <inertia ixx="4.05" ixy="0" ixz="0" iyy="9.82" iyz="0" izz="12.25"/>
    </inertial>
    <gazebo>
		</gazebo>
  </link>
  <link name="link_0">
    <visual>
      <geometry>
        <cylinder length="0.15" radius="0.2"/>
      </geometry>
      <origin rpy="1.57075 0 0"/>
      <material name="blue"/>
    </visual>
    <collision>
      <geometry>
        <cylinder length="0.15" radius="0.2"/>
      </geometry>
      <origin rpy="1.57075 0 0"/>
    </collision>
    <inertial>
      <mass value="12.01"/>
      <inertia ixx=".14" ixy="0" ixz="0" iyy="0.24" iyz="0" izz=".14"/>
    </inertial>
    <gazebo>
			</gazebo>
  </link>
  <joint name="joint_0" type="continuous">
    <parent link="base_link"/>
    <child link="link_0"/>
    <axis xyz="0 1 0"/>
    <origin rpy="0 0 0" xyz="0.3 0.375 -0.075"/>
    <gazebo>
			</gazebo>
  </joint>
  <link name="link_1">
    <visual>
      <geometry>
        <cylinder length="0.15" radius="0.2"/>
      </geometry>
      <origin rpy="1.57075 0 0"/>
      <material name="blue"/>
    </visual>
    <collision>
      <geometry>
        <cylinder length="0.15" radius="0.2"/>
      </geometry>
      <origin rpy="1.57075 0 0"/>
    </collision>
    <inertial>
      <mass value="12.01"/>
      <inertia ixx=".14" ixy="0" ixz="0" iyy="0.24" iyz="0" izz=".14"/>
    </inertial>
    <gazebo>
			</gazebo>
  </link>
  <joint name="joint_1" type="continuous">
    <parent link="base_link"/>
    <child link="link_1"/>
    <axis xyz="0 1 0"/>
    <origin rpy="0 0 0" xyz="0.3 -0.375 -0.075"/>
    <gazebo>
			</gazebo>
  </joint>
  <link name="link_2">
    <visual>
      <geometry>
        <cylinder length="0.15" radius="0.2"/>
      </geometry>
      <origin rpy="1.57075 0 0"/>
      <material name="blue"/>
    </visual>
    <collision>
      <geometry>
        <cylinder length="0.15" radius="0.2"/>
      </geometry>
      <origin rpy="1.57075 0 0"/>
    </collision>
    <inertial>
      <mass value="12.01"/>
      <inertia ixx=".14" ixy="0" ixz="0" iyy="0.24" iyz="0" izz=".14"/>
    </inertial>
    <gazebo>
			</gazebo>
  </link>
  <joint name="joint_2" type="continuous">
    <parent link="base_link"/>
    <child link="link_2"/>
    <axis xyz="0 1 0"/>
    <origin rpy="0 0 0" xyz="-0.3 0.375 -0.075"/>
    <gazebo>
			</gazebo>
  </joint>
  <link name="link_3">
    <visual>
      <geometry>
        <cylinder length="0.15" radius="0.2"/>
      </geometry>
      <origin rpy="1.57075 0 0"/>
      <material name="blue"/>
    </visual>
    <collision>
      <geometry>
        <cylinder length="0.15" radius="0.2"/>
      </geometry>
      <origin rpy="1.57075 0 0"/>
    </collision>
    <inertial>
      <mass value="12.01"/>
      <inertia ixx=".14" ixy="0" ixz="0" iyy="0.24" iyz="0" izz=".14"/>
    </inertial>
    <gazebo>
			</gazebo>
  </link>
  <joint name="joint_3" type="continuous">
    <parent link="base_link"/>
    <child link="link_3"/>
    <axis xyz="0 1 0"/>
    <origin rpy="0 0 0" xyz="-0.3 -0.375 -0.075"/>
    <gazebo>
			</gazebo>
  </joint>
</robot>

