<?xml version="1.0"?>

<!--Name of robot-->
<robot xmlns:xacro="http://www.ros.org/wiki/xacro" name="Roberto_MkI">

  <!--Naming Materials-->
  <material name="blue">
    <color rgba="0 0 0.8 1"/>
  </material>

  <material name="white">
    <color rgba="1 1 1 1"/>
  </material>

	<!--Add <gazebo> element to <robot>, <link>, and <joint> elements-->
	<gazebo>
	</gazebo>

  <!--Xacro Macros-->
  <!--Body Macros-->
  <xacro:property name="body_size" value="1.0 0.6 0.3" />

  <!--Wheel Macros-->
  <xacro:property name="wheel_len" value=".15" />
  <xacro:property name="wheel_rad" value=".2" />
  <xacro:property name="wheel_origin" value="1.57075 0 0" />
  <xacro:macro name="wheel" params="suffix reflect_x reflect_y reflect_z">
    <link name="link_${suffix}">
      <visual>
        <geometry>
          <cylinder length="${wheel_len}" radius="${wheel_rad}"/>
        </geometry>
        <origin rpy="${wheel_origin}"/>
        <material name="blue"/>
      </visual>
      <collision>
        <geometry>
          <cylinder length="${wheel_len}" radius="${wheel_rad}"/>
        </geometry>
        <origin rpy="${wheel_origin}"/>
      </collision>
      <inertial>
        <mass value="12.01"/>
        <inertia ixx=".14" ixy="0" ixz="0" iyy="0.24" iyz="0" izz=".14"/>
      </inertial>
			<gazebo>
			</gazebo>
    </link>

    <joint name="joint_${suffix}" type="continuous">
      <parent link="base_link"/>
      <child link="link_${suffix}"/>
      <axis xyz="0 1 0"/>
      <origin rpy="0 0 0" xyz="${reflect_x * 0.3} ${reflect_y * 0.375} ${reflect_z * 0.075}"/>
			<gazebo>
			</gazebo>
    </joint>
  </xacro:macro>

  <!--Links-->
  <!--Body(base_link)-->
  <link name="base_link">
    <!--Visual-->
    <visual>
      <geometry>
        <box size="${body_size}"/>
      </geometry>
        <material name="white"/>
    </visual>
    <!--Collision-->
    <collision>
      <geometry>
        <box size="${body_size}"/>
      </geometry>
    </collision>
    <inertial>
      <mass value="108.09"/>
      <!--inertia: required by Gazebo-->  
      <!--6 values: ixx ixy ixz iyy iyz izz-->
      <inertia ixx="4.05" ixy="0" ixz="0" iyy="9.82" iyz="0" izz="12.25"/>
    </inertial>
		<gazebo>
		</gazebo>
  </link>

  <!--wheel/joint_0-->
  <xacro:wheel suffix="0" reflect_x="1" reflect_y="1" reflect_z="-1" />
  <!--wheel/joint_1-->
  <xacro:wheel suffix="1" reflect_x="1" reflect_y="-1" reflect_z="-1" />
  <!--wheel/joint_2-->
  <xacro:wheel suffix="2" reflect_x="-1" reflect_y="1" reflect_z="-1" />
  <!--wheel/joint_3-->
  <xacro:wheel suffix="3" reflect_x="-1" reflect_y="-1" reflect_z="-1" />

</robot>
